2022-07-31 14:07:31,974 INFO    MainThread:9528 [wandb_setup.py:_flush():76] Configure stats pid to 9528
2022-07-31 14:07:31,974 INFO    MainThread:9528 [wandb_setup.py:_flush():76] Loading settings from C:\Users\znk\.config\wandb\settings
2022-07-31 14:07:31,974 INFO    MainThread:9528 [wandb_setup.py:_flush():76] Loading settings from c:\Users\znk\Desktop\Programme\image-processing-by-dl\segmentation\U-Net\wandb\settings
2022-07-31 14:07:31,975 INFO    MainThread:9528 [wandb_setup.py:_flush():76] Loading settings from environment variables: {}
2022-07-31 14:07:31,975 INFO    MainThread:9528 [wandb_setup.py:_flush():76] Inferring run settings from compute environment: {'program': '<python with no main file>'}
2022-07-31 14:07:31,975 INFO    MainThread:9528 [wandb_init.py:_log_setup():461] Logging user logs to c:\Users\znk\Desktop\Programme\image-processing-by-dl\segmentation\U-Net\wandb\run-20220731_140731-22lcfsam\logs\debug.log
2022-07-31 14:07:31,975 INFO    MainThread:9528 [wandb_init.py:_log_setup():462] Logging internal logs to c:\Users\znk\Desktop\Programme\image-processing-by-dl\segmentation\U-Net\wandb\run-20220731_140731-22lcfsam\logs\debug-internal.log
2022-07-31 14:07:31,975 INFO    MainThread:9528 [wandb_init.py:_jupyter_setup():411] configuring jupyter hooks <wandb.sdk.wandb_init._WandbInit object at 0x0000016CF5441A90>
2022-07-31 14:07:31,976 INFO    MainThread:9528 [wandb_init.py:init():495] calling init triggers
2022-07-31 14:07:31,976 INFO    MainThread:9528 [wandb_init.py:init():498] wandb.init called with sweep_config: {}
config: {}
2022-07-31 14:07:31,976 INFO    MainThread:9528 [wandb_init.py:init():548] starting backend
2022-07-31 14:07:31,976 INFO    MainThread:9528 [backend.py:_multiprocessing_setup():97] multiprocessing start_methods=spawn, using: spawn
2022-07-31 14:07:31,983 INFO    MainThread:9528 [backend.py:ensure_launched():217] starting backend process...
2022-07-31 14:07:32,097 INFO    MainThread:9528 [backend.py:ensure_launched():222] started backend process with pid: 9136
2022-07-31 14:07:32,097 INFO    MainThread:9528 [wandb_init.py:init():558] backend started and connected
2022-07-31 14:07:32,099 INFO    MainThread:9528 [wandb_run.py:_label_probe_notebook():1084] probe notebook
2022-07-31 14:07:32,100 INFO    MainThread:9528 [wandb_run.py:_label_probe_notebook():1094] Unable to probe notebook: 'NoneType' object has no attribute 'get'
2022-07-31 14:07:32,101 INFO    MainThread:9528 [wandb_init.py:init():634] updated telemetry
2022-07-31 14:07:32,184 INFO    MainThread:9528 [wandb_init.py:init():665] communicating run to backend with 30 second timeout
2022-07-31 14:07:36,719 INFO    MainThread:9528 [wandb_run.py:_on_init():1919] communicating current version
2022-07-31 14:07:41,315 INFO    MainThread:9528 [wandb_run.py:_on_init():1923] got version response 
2022-07-31 14:07:41,315 INFO    MainThread:9528 [wandb_init.py:init():700] starting run threads in backend
2022-07-31 14:07:45,158 INFO    MainThread:9528 [wandb_run.py:_console_start():1893] atexit reg
2022-07-31 14:07:45,159 INFO    MainThread:9528 [wandb_run.py:_redirect():1766] redirect: SettingsConsole.WRAP
2022-07-31 14:07:45,160 INFO    MainThread:9528 [wandb_run.py:_redirect():1803] Wrapping output streams.
2022-07-31 14:07:45,162 INFO    MainThread:9528 [wandb_run.py:_redirect():1827] Redirects installed.
2022-07-31 14:07:45,162 INFO    MainThread:9528 [wandb_init.py:init():732] run started, returning control to user process
2022-07-31 14:07:45,167 INFO    MainThread:9528 [wandb_init.py:_pause_backend():374] pausing backend
2022-07-31 14:07:45,167 INFO    MainThread:9528 [jupyter.py:save_ipynb():377] not saving jupyter notebook
2022-07-31 14:09:17,274 INFO    MainThread:9528 [wandb_init.py:_resume_backend():383] resuming backend
2022-07-31 14:09:21,219 ERROR   MainThread:9528 [retry.py:__call__():132] Retry attempt failed:
Traceback (most recent call last):
  File "c:\Users\znk\anaconda3\envs\kaggle\lib\site-packages\urllib3\connectionpool.py", line 700, in urlopen
    self._prepare_proxy(conn)
  File "c:\Users\znk\anaconda3\envs\kaggle\lib\site-packages\urllib3\connectionpool.py", line 996, in _prepare_proxy
    conn.connect()
  File "c:\Users\znk\anaconda3\envs\kaggle\lib\site-packages\urllib3\connection.py", line 364, in connect
    self.sock = conn = self._connect_tls_proxy(hostname, conn)
  File "c:\Users\znk\anaconda3\envs\kaggle\lib\site-packages\urllib3\connection.py", line 499, in _connect_tls_proxy
    socket = ssl_wrap_socket(
  File "c:\Users\znk\anaconda3\envs\kaggle\lib\site-packages\urllib3\util\ssl_.py", line 453, in ssl_wrap_socket
    ssl_sock = _ssl_wrap_socket_impl(sock, context, tls_in_tls)
  File "c:\Users\znk\anaconda3\envs\kaggle\lib\site-packages\urllib3\util\ssl_.py", line 495, in _ssl_wrap_socket_impl
    return ssl_context.wrap_socket(sock)
  File "c:\Users\znk\anaconda3\envs\kaggle\lib\ssl.py", line 500, in wrap_socket
    return self.sslsocket_class._create(
  File "c:\Users\znk\anaconda3\envs\kaggle\lib\ssl.py", line 1040, in _create
    self.do_handshake()
  File "c:\Users\znk\anaconda3\envs\kaggle\lib\ssl.py", line 1309, in do_handshake
    self._sslobj.do_handshake()
ssl.SSLEOFError: EOF occurred in violation of protocol (_ssl.c:1131)

During handling of the above exception, another exception occurred:

Traceback (most recent call last):
  File "c:\Users\znk\anaconda3\envs\kaggle\lib\site-packages\requests\adapters.py", line 489, in send
    resp = conn.urlopen(
  File "c:\Users\znk\anaconda3\envs\kaggle\lib\site-packages\urllib3\connectionpool.py", line 787, in urlopen
    retries = retries.increment(
  File "c:\Users\znk\anaconda3\envs\kaggle\lib\site-packages\urllib3\util\retry.py", line 592, in increment
    raise MaxRetryError(_pool, url, error or ResponseError(cause))
urllib3.exceptions.MaxRetryError: HTTPSConnectionPool(host='api.wandb.ai', port=443): Max retries exceeded with url: /graphql (Caused by SSLError(SSLEOFError(8, 'EOF occurred in violation of protocol (_ssl.c:1131)')))

During handling of the above exception, another exception occurred:

Traceback (most recent call last):
  File "c:\Users\znk\anaconda3\envs\kaggle\lib\site-packages\wandb\sdk\lib\retry.py", line 108, in __call__
    result = self._call_fn(*args, **kwargs)
  File "c:\Users\znk\anaconda3\envs\kaggle\lib\site-packages\wandb\apis\public.py", line 207, in execute
    return self._client.execute(*args, **kwargs)
  File "c:\Users\znk\anaconda3\envs\kaggle\lib\site-packages\wandb\vendor\gql-0.2.0\wandb_gql\client.py", line 52, in execute
    result = self._get_result(document, *args, **kwargs)
  File "c:\Users\znk\anaconda3\envs\kaggle\lib\site-packages\wandb\vendor\gql-0.2.0\wandb_gql\client.py", line 60, in _get_result
    return self.transport.execute(document, *args, **kwargs)
  File "c:\Users\znk\anaconda3\envs\kaggle\lib\site-packages\wandb\vendor\gql-0.2.0\wandb_gql\transport\requests.py", line 38, in execute
    request = requests.post(self.url, **post_args)
  File "c:\Users\znk\anaconda3\envs\kaggle\lib\site-packages\requests\api.py", line 115, in post
    return request("post", url, data=data, json=json, **kwargs)
  File "c:\Users\znk\anaconda3\envs\kaggle\lib\site-packages\requests\api.py", line 59, in request
    return session.request(method=method, url=url, **kwargs)
  File "c:\Users\znk\anaconda3\envs\kaggle\lib\site-packages\requests\sessions.py", line 587, in request
    resp = self.send(prep, **send_kwargs)
  File "c:\Users\znk\anaconda3\envs\kaggle\lib\site-packages\requests\sessions.py", line 701, in send
    r = adapter.send(request, **kwargs)
  File "c:\Users\znk\anaconda3\envs\kaggle\lib\site-packages\requests\adapters.py", line 563, in send
    raise SSLError(e, request=request)
requests.exceptions.SSLError: HTTPSConnectionPool(host='api.wandb.ai', port=443): Max retries exceeded with url: /graphql (Caused by SSLError(SSLEOFError(8, 'EOF occurred in violation of protocol (_ssl.c:1131)')))
2022-07-31 14:09:54,643 ERROR   MainThread:9528 [retry.py:__call__():132] Retry attempt failed:
Traceback (most recent call last):
  File "c:\Users\znk\anaconda3\envs\kaggle\lib\site-packages\urllib3\connectionpool.py", line 700, in urlopen
    self._prepare_proxy(conn)
  File "c:\Users\znk\anaconda3\envs\kaggle\lib\site-packages\urllib3\connectionpool.py", line 996, in _prepare_proxy
    conn.connect()
  File "c:\Users\znk\anaconda3\envs\kaggle\lib\site-packages\urllib3\connection.py", line 364, in connect
    self.sock = conn = self._connect_tls_proxy(hostname, conn)
  File "c:\Users\znk\anaconda3\envs\kaggle\lib\site-packages\urllib3\connection.py", line 499, in _connect_tls_proxy
    socket = ssl_wrap_socket(
  File "c:\Users\znk\anaconda3\envs\kaggle\lib\site-packages\urllib3\util\ssl_.py", line 453, in ssl_wrap_socket
    ssl_sock = _ssl_wrap_socket_impl(sock, context, tls_in_tls)
  File "c:\Users\znk\anaconda3\envs\kaggle\lib\site-packages\urllib3\util\ssl_.py", line 495, in _ssl_wrap_socket_impl
    return ssl_context.wrap_socket(sock)
  File "c:\Users\znk\anaconda3\envs\kaggle\lib\ssl.py", line 500, in wrap_socket
    return self.sslsocket_class._create(
  File "c:\Users\znk\anaconda3\envs\kaggle\lib\ssl.py", line 1040, in _create
    self.do_handshake()
  File "c:\Users\znk\anaconda3\envs\kaggle\lib\ssl.py", line 1309, in do_handshake
    self._sslobj.do_handshake()
ssl.SSLEOFError: EOF occurred in violation of protocol (_ssl.c:1131)

During handling of the above exception, another exception occurred:

Traceback (most recent call last):
  File "c:\Users\znk\anaconda3\envs\kaggle\lib\site-packages\requests\adapters.py", line 489, in send
    resp = conn.urlopen(
  File "c:\Users\znk\anaconda3\envs\kaggle\lib\site-packages\urllib3\connectionpool.py", line 787, in urlopen
    retries = retries.increment(
  File "c:\Users\znk\anaconda3\envs\kaggle\lib\site-packages\urllib3\util\retry.py", line 592, in increment
    raise MaxRetryError(_pool, url, error or ResponseError(cause))
urllib3.exceptions.MaxRetryError: HTTPSConnectionPool(host='api.wandb.ai', port=443): Max retries exceeded with url: /graphql (Caused by SSLError(SSLEOFError(8, 'EOF occurred in violation of protocol (_ssl.c:1131)')))

During handling of the above exception, another exception occurred:

Traceback (most recent call last):
  File "c:\Users\znk\anaconda3\envs\kaggle\lib\site-packages\wandb\sdk\lib\retry.py", line 108, in __call__
    result = self._call_fn(*args, **kwargs)
  File "c:\Users\znk\anaconda3\envs\kaggle\lib\site-packages\wandb\sdk\internal\internal_api.py", line 158, in execute
    return self.client.execute(*args, **kwargs)
  File "c:\Users\znk\anaconda3\envs\kaggle\lib\site-packages\wandb\vendor\gql-0.2.0\wandb_gql\client.py", line 52, in execute
    result = self._get_result(document, *args, **kwargs)
  File "c:\Users\znk\anaconda3\envs\kaggle\lib\site-packages\wandb\vendor\gql-0.2.0\wandb_gql\client.py", line 60, in _get_result
    return self.transport.execute(document, *args, **kwargs)
  File "c:\Users\znk\anaconda3\envs\kaggle\lib\site-packages\wandb\vendor\gql-0.2.0\wandb_gql\transport\requests.py", line 38, in execute
    request = requests.post(self.url, **post_args)
  File "c:\Users\znk\anaconda3\envs\kaggle\lib\site-packages\requests\api.py", line 115, in post
    return request("post", url, data=data, json=json, **kwargs)
  File "c:\Users\znk\anaconda3\envs\kaggle\lib\site-packages\requests\api.py", line 59, in request
    return session.request(method=method, url=url, **kwargs)
  File "c:\Users\znk\anaconda3\envs\kaggle\lib\site-packages\requests\sessions.py", line 587, in request
    resp = self.send(prep, **send_kwargs)
  File "c:\Users\znk\anaconda3\envs\kaggle\lib\site-packages\requests\sessions.py", line 701, in send
    r = adapter.send(request, **kwargs)
  File "c:\Users\znk\anaconda3\envs\kaggle\lib\site-packages\requests\adapters.py", line 563, in send
    raise SSLError(e, request=request)
requests.exceptions.SSLError: HTTPSConnectionPool(host='api.wandb.ai', port=443): Max retries exceeded with url: /graphql (Caused by SSLError(SSLEOFError(8, 'EOF occurred in violation of protocol (_ssl.c:1131)')))
